Workbook

Sheet bus
B1: name | C1: vn_kv | D1: type | E1: zone | F1: in_service | G1: min_vm_pu | H1: max_vm_pu
A2: 0 | B2: EEM220 | C2: 220 | D2: b | E2: Station Eemshaven 220 | F2: TRUE | G2: 0.95 | H2: 1.05
A3: 1 | B3: ENS220 | C3: 220 | D3: b | E3: Station Ens 220 | F3: TRUE | G3: 0.95 | H3: 1.05
A4: 2 | B4: HSW220 | C4: 220 | D4: b | E4: Station Hessenweg 220 | F4: TRUE | G4: 0.95 | H4: 1.05
A5: 3 | B5: LSM220 | C5: 220 | D5: b | E5: Station Louwsmeer 220 | F5: TRUE | G5: 0.95 | H5: 1.05
A6: 4 | B6: MEE220 | C6: 220 | D6: b | E6: Station Meeden 220 | F6: TRUE | G6: 0.95 | H6: 1.05
A7: 5 | B7: OHK220 | C7: 220 | D7: b | E7: Station Oudehaske 220 | F7: TRUE | G7: 0.95 | H7: 1.05
A8: 6 | B8: RBB220 | C8: 220 | D8: b | E8: Station Robbenplaat 220 | F8: TRUE | G8: 0.95 | H8: 1.05
A9: 7 | B9: VVL220 | C9: 220 | D9: b | E9: Station Vierverlaten 220 | F9: TRUE | G9: 0.95 | H9: 1.05
A10: 8 | B10: WEW220 | C10: 220 | D10: b | E10: Station Weiwerd 220 | F10: TRUE | G10: 0.95 | H10: 1.05
A11: 9 | B11: ZYV220 | C11: 220 | D11: b | E11: Station Zeyerveen 220 | F11: TRUE | G11: 0.95 | H11: 1.05
A12: 10 | B12: BKK380 | C12: 380 | D12: b | E12: Station Breukelen Kortrijk 380 | F12: TRUE | G12: 0.95 | H12: 1.05
A13: 11 | B13: BSL380 | C13: 380 | D13: b | E13: Station Borssele 380 | F13: TRUE | G13: 0.95 | H13: 1.05
... A54: 52 | B54: VOB380 | C54: 380 | D54: b | E54: Station Veenoord Boerdijk 380 | F54: TRUE | G54: 0.95 | H54: 1.05

Sheet load
B1: name | C1: bus | D1: p_mw | E1: q_mvar | F1: const_z_percent | G1: const_i_percent | H1: sn_mva | I1: scaling | J1: in_service | K1: type | L1: controllable
A2: 0 | B2: HSW220 | C2: 2 | D2: 255.23669 | E2: 83.892243 | F2: 0 | G2: 0 | I2: 1 | J2: TRUE | K2: wye | L2: FALSE
A3: 1 | B3: LSM220 | C3: 3 | D3: 623.94963 | E3: 205.08233 | F3: 0 | G3: 0 | I3: 1 | J3: TRUE | K3: wye | L3: FALSE
A4: 2 | B4: MEE220 | C4: 4 | D4: 212.67141 | E4: 69.901711 | F4: 0 | G4: 0 | I4: 1 | J4: TRUE | K4: wye | L4: FALSE
A5: 3 | B5: OHK220 | C5: 5 | D5: 89.182721 | E5: 29.312943 | F5: 0 | G5: 0 | I5: 1 | J5: TRUE | K5: wye | L5: FALSE
A6: 4 | B6: RBB220 | C6: 6 | D6: 771.92612 | E6: 253.71985 | F6: 0 | G6: 0 | I6: 1 | J6: TRUE | K6: wye | L6: FALSE
A7: 5 | B7: WEW220 | C7: 8 | D7: 131.27299 | E7: 43.147344 | F7: 0 | G7: 0 | I7: 1 | J7: TRUE | K7: wye | L7: FALSE
A8: 6 | B8: ZYV220 | C8: 9 | D8: 431.29961 | E8: 141.76133 | F8: 0 | G8: 0 | I8: 1 | J8: TRUE | K8: wye | L8: FALSE
A9: 7 | B9: BKK380 | C9: 10 | D9: 1279.3498 | E9: 420.50195 | F9: 0 | G9: 0 | I9: 1 | J9: TRUE | K9: wye | L9: FALSE
A10: 8 | B10: BSL380 | C10: 11 | D10: 536.52071 | E10: 176.34583 | F10: 0 | G10: 0 | I10: 1 | J10: TRUE | K10: wye | L10: FALSE
A11: 9 | B11: BVW380 | C11: 12 | D11: 394.43093 | E11: 129.64318 | F11: 0 | G11: 0 | I11: 1 | J11: TRUE | K11: wye | L11: FALSE
A12: 10 | B12: BWK380 | C12: 13 | D12: 162.83887 | E12: 53.522547 | F12: 0 | G12: 0 | I12: 1 | J12: TRUE | K12: wye | L12: FALSE
A13: 11 | B13: CST380 | C13: 14 | D13: 217.11852 | E13: 71.363405 | F13: 0 | G13: 0 | I13: 1 | J13: TRUE | K13: wye | L13: FALSE
... A46: 44 | B46: 380kV Germany (Wesel) - Doetichem | C46: 40 | D46: 599.2576 | E46: 196.96645 | F46: 0 | G46: 0 | I46: 1 | J46: TRUE | K46: wye | L46: FALSE

Sheet gen
B1: name | C1: bus | D1: p_mw | E1: vm_pu | F1: sn_mva | G1: min_q_mvar | H1: max_q_mvar | I1: scaling | J1: slack | K1: in_service | L1: slack_weight | M1: type | N1: controllable | O1: min_p_mw | P1: max_p_mw
A2: 0 | B2: 380kV Germany (Diele) - Groningen | C2: 38 | D2: =0.05*2000 -> 100 | E2: 1 | G2: -5000 | H2: 5000 | I2: 1 | J2: FALSE | K2: TRUE | L2: 0 | M2: External Grid | N2: TRUE | O2: -1972 | P2: 1972
A3: 1 | B3: 380kV Germany (Gronau) - Enschede | C3: 39 | D3: =0.05*2000 -> 100 | E3: 1 | G3: -5000 | H3: 5000 | I3: 1 | J3: FALSE | K3: TRUE | L3: 0 | M3: External Grid | N3: TRUE | O3: -1972 | P3: 1972
A4: 2 | B4: 380kV Germany (Rommerskirchen) - Roermond | C4: 41 | D4: =0.05*2000 -> 100 | E4: 1 | G4: -5000 | H4: 5000 | I4: 1 | J4: FALSE | K4: TRUE | L4: 0 | M4: External Grid | N4: TRUE | O4: -986 | P4: 986
A5: 3 | B5: 380kV Germany (Siersdorf) - Roermond | C5: 42 | D5: =0.05*2000 -> 100 | E5: 1 | G5: -5000 | H5: 5000 | I5: 1 | J5: FALSE | K5: TRUE | L5: 0 | M5: External Grid | N5: TRUE | O5: -986 | P5: 986
A6: 4 | B6: 380kV Belgium (Van Eyck) - Maasbracht | C6: 43 | D6: =0.05*2000 -> 100 | E6: 1 | G6: -5000 | H6: 5000 | I6: 1 | J6: FALSE | K6: TRUE | L6: 0 | M6: External Grid | N6: TRUE | O6: -1128 | P6: 1128
A7: 5 | B7: 380kV Belgium (Zandvliet) - Rilland | C7: 44 | D7: =0.05*2000 -> 100 | E7: 1 | G7: -5000 | H7: 5000 | I7: 1 | J7: FALSE | K7: TRUE | L7: 0 | M7: External Grid | N7: TRUE | O7: -1128 | P7: 1128
A8: 6 | B8: 380kV Britain (BritNed) - Maasvlakte | C8: 35 | D8: =0.050432*2000 -> 100.864 | E8: 1 | G8: -5000 | H8: 5000 | I8: 1 | J8: FALSE | K8: TRUE | L8: 0 | M8: External Grid | N8: TRUE | O8: -1000 | P8: 1000
A9: 7 | B9: 380kV Denmark (COBRA) - Eemshaven | C9: 36 | D9: =0.05*2000 -> 100 | E9: 1 | G9: -5000 | H9: 5000 | I9: 1 | J9: FALSE | K9: TRUE | L9: 0 | M9: External Grid | N9: TRUE | O9: -700 | P9: 700
A10: 8 | B10: 380kV Norway (NorNed) - Eemshaven | C10: 37 | D10: =0.24611*2000 -> 492.22 | E10: 1 | G10: -5000 | H10: 5000 | I10: 1 | J10: FALSE | K10: TRUE | L10: 0 | M10: External Grid | N10: TRUE | O10: -700 | P10: 700
A11: 9 | B11: Pergen Power Station | C11: 28 | D11: =0.6*P11 -> 75 | E11: 1 | G11: =-H11 -> -41.25 | H11: =0.33*P11 -> 41.25 | I11: 1 | J11: FALSE | K11: TRUE | L11: 0 | M11: CCGT | N11: TRUE | O11: 0 | P11: 125
A12: 10 | B12: Pergen Power Station | C12: 28 | D12: =0.6*P12 -> 75 | E12: 1 | G12: =-H12 -> -41.25 | H12: =0.33*P12 -> 41.25 | I12: 1 | J12: FALSE | K12: TRUE | L12: 0 | M12: CCGT | N12: TRUE | O12: 0 | P12: 125
A13: 11 | B13: Amylum Gas | C13: 29 | D13: =0.6*P13 -> 4.2 | E13: 1 | G13: =-H13 -> -2.31 | H13: =0.33*P13 -> 2.31 | I13: 1 | J13: FALSE | K13: TRUE | L13: 0 | M13: CCGT | N13: TRUE | O13: 0 | P13: 7
A14: 12 | B14: Corus CHP | C14: 12 | D14: =0.6*P14 -> 22.8 | E14: 1 | G14: =-H14 -> -12.54 | H14: =0.33*P14 -> 12.54 | I14: 1 | J14: FALSE | K14: TRUE | L14: 0 | M14: CCGT | N14: TRUE | O14: 0 | P14: 38
A15: 13 | B15: Kerncentrale Borssele | C15: 11 | D15: =0.98*P15 -> 475.3 | E15: 1 | G15: =-H15 -> -160.05 | H15: =0.33*P15 -> 160.05 | I15: 1 | J15: FALSE | K15: TRUE | L15: 0 | M15: Nuclear | N15: TRUE | O15: 0 | P15: 485
A16: 14 | B16: Attero Waste Incineration Plant | C16: 9 | D16: =0.6*P16 -> 28.8 | E16: 1 | G16: =-H16 -> -15.84 | H16: =0.33*P16 -> 15.84 | I16: 1 | J16: FALSE | K16: TRUE | L16: 0 | M16: Waste | N16: TRUE | O16: 0 | P16: 48
A17: 15 | B17: ELSTA centrale | C17: 11 | D17: =0.6*P17 -> 273 | E17: 1 | G17: =-H17 -> -150.15 | H17: =0.33*P17 -> 150.15 | I17: 1 | J17: FALSE | K17: TRUE | L17: 0 | M17: CCGT | N17: TRUE | O17: 0 | P17: 455
A18: 16 | B18: EnecoGen | C18: 28 | D18: =0.6*P18 -> 506.4 | E18: 1 | G18: =-H18 -> -278.52 | H18: =0.33*P18 -> 278.52 | I18: 1 | J18: FALSE | K18: TRUE | L18: 0 | M18: CCGT | N18: TRUE | O18: 0 | P18: 844
A19: 17 | B19: Centrale Bergum | C19: 3 | D19: =0.6*P19 -> 43.2 | E19: 1 | G19: =-H19 -> -23.76 | H19: =0.33*P19 -> 23.76 | I19: 1 | J19: FALSE | K19: TRUE | L19: 0 | M19: Combi | N19: TRUE | O19: 0 | P19: 72
A20: 18 | B20: Centrale Bergum | C20: 3 | D20: =0.6*P20 -> 43.2 | E20: 1 | G20: =-H20 -> -23.76 | H20: =0.33*P20 -> 23.76 | I20: 1 | J20: FALSE | K20: TRUE | L20: 0 | M20: Combi | N20: TRUE | O20: 0 | P20: 72
A21: 19 | B21: Eemscentrale | C21: 6 | D21: =0.6*P21 -> 78.6 | E21: 1 | G21: =-H21 -> -43.23 | H21: =0.33*P21 -> 43.23 | I21: 1 | J21: FALSE | K21: TRUE | L21: 0 | M21: Combi | N21: TRUE | O21: 0 | P21: 131
A22: 20 | B22: Eemscentrale | C22: 6 | D22: =0.6*P22 -> 215.4 | E22: 1 | G22: =-H22 -> -118.47 | H22: =0.33*P22 -> 118.47 | I22: 1 | J22: FALSE | K22: TRUE | L22: 0 | M22: CCGT | N22: TRUE | O22: 0 | P22: 359
A23: 21 | B23: Eemscentrale | C23: 6 | D23: =0.6*P23 -> 215.4 | E23: 1 | G23: =-H23 -> -118.47 | H23: =0.33*P23 -> 118.47 | I23: 1 | J23: FALSE | K23: TRUE | L23: 0 | M23: CCGT | N23: TRUE | O23: 0 | P23: 359
A24: 22 | B24: Eemscentrale | C24: 6 | D24: =0.6*P24 -> 216.6 | E24: 1 | G24: =-H24 -> -119.13 | H24: =0.33*P24 -> 119.13 | I24: 1 | J24: FALSE | K24: TRUE | L24: 0 | M24: CCGT | N24: TRUE | O24: 0 | P24: 361
A25: 23 | B25: Eemscentrale | C25: 18 | D25: =0.6*P25 -> 215.4 | E25: 1 | G25: =-H25 -> -118.47 | H25: =0.33*P25 -> 118.47 | I25: 1 | J25: FALSE | K25: TRUE | L25: 0 | M25: CCGT | N25: TRUE | O25: 0 | P25: 359
A26: 24 | B26: Eemscentrale | C26: 18 | D26: =0.6*P26 -> 216 | E26: 1 | G26: =-H26 -> -118.8 | H26: =0.33*P26 -> 118.8 | I26: 1 | J26: FALSE | K26: TRUE | L26: 0 | M26: CCGT | N26: TRUE | O26: 0 | P26: 360
A27: 25 | B27: Maximacentrale | C27: 25 | D27: =0.6*P27 -> 255.6 | E27: 1 | G27: =-H27 -> -140.58 | H27: =0.33*P27 -> 140.58 | I27: 1 | J27: FALSE | K27: TRUE | L27: 0 | M27: CCGT | N27: TRUE | O27: 0 | P27: 426
... A82: 80 | B82: ARN B.V. Weurt | C82: 48 | D82: =0.6*P82 -> 30 | E82: 1 | G82: =-H82 -> -16.5 | H82: =0.33*P82 -> 16.5 | I82: 1 | J82: FALSE | K82: TRUE | L82: 0 | M82: Waste | N82: TRUE | O82: 0 | P82: 50
A83: 81 | B83: Windpark Gemini | C83: 21 | D83: =0.35*gen!P83 -> 210 | E83: 1 | G83: =-H83 -> -198 | H83: =0.33*gen!P83 -> 198 | I83: 1 | J83: FALSE | K83: TRUE | L83: 0 | M83: WP | N83: TRUE | O83: 0 | P83: 600
A84: 82 | B84: Windpark Luchterduinen | C84: 13 | D84: =0.35*gen!P84 -> 45.15 | E84: 1 | G84: =-H84 -> -42.57 | H84: =0.33*gen!P84 -> 42.57 | I84: 1 | J84: FALSE | K84: TRUE | L84: 0 | M84: WP | N84: TRUE | O84: 0 | P84: 129
A85: 83 | B85: Windpark Prinses Amalia | C85: 12 | D85: =0.35*gen!P85 -> 42 | E85: 1 | G85: =-H85 -> -39.6 | H85: =0.33*gen!P85 -> 39.6 | I85: 1 | J85: FALSE | K85: TRUE | L85: 0 | M85: WP | N85: TRUE | O85: 0 | P85: 120
A86: 84 | B86: Windpark NoordzeeWind | C86: 12 | D86: =0.35*gen!P86 -> 37.8 | E86: 1 | G86: =-H86 -> -35.64 | H86: =0.33*gen!P86 -> 35.64 | I86: 1 | J86: FALSE | K86: TRUE | L86: 0 | M86: WP | N86: TRUE | O86: 0 | P86: 108
A87: 85 | B87: Windpark Prinses Alexia | C87: 15 | D87: =0.35*gen!P87 -> 42.7 | E87: 1 | G87: =-H87 -> -40.26 | H87: =0.33*gen!P87 -> 40.26 | I87: 1 | J87: FALSE | K87: TRUE | L87: 0 | M87: WP | N87: TRUE | O87: 0 | P87: 122
A88: 86 | B88: Windpark Westereems | C88: 6 | D88: =0.35*gen!P88 -> 59.85 | E88: 1 | G88: =-H88 -> -56.43 | H88: =0.33*gen!P88 -> 56.43 | I88: 1 | J88: FALSE | K88: TRUE | L88: 0 | M88: WP | N88: TRUE | O88: 0 | P88: 171
A89: 87 | B89: Windpark Noordoostpolder Water | C89: 5 | D89: =0.35*gen!P89 -> 50.4 | E89: 1 | G89: =-H89 -> -47.52 | H89: =0.33*gen!P89 -> 47.52 | I89: 1 | J89: FALSE | K89: TRUE | L89: 0 | M89: WP | N89: TRUE | O89: 0 | P89: 144
A90: 88 | B90: Windpark Noordoostpolder Land | C90: 5 | D90: =0.35*gen!P90 -> 99.75 | E90: 1 | G90: =-H90 -> -94.05 | H90: =0.33*gen!P90 -> 94.05 | I90: 1 | J90: FALSE | K90: TRUE | L90: 0 | M90: WP | N90: TRUE | O90: 0 | P90: 285
A91: 89 | B91: Windpark Krammer | C91: 28 | D91: =0.35*gen!P91 -> 35.7 | E91: 1 | G91: =-H91 -> -33.66 | H91: =0.33*gen!P91 -> 33.66 | I91: 1 | J91: FALSE | K91: TRUE | L91: 0 | M91: WP | N91: TRUE | O91: 0 | P91: 102
A92: 90 | B92: Windpark Kreekraksluis | C92: 30 | D92: =0.35*gen!P92 -> 28.875 | E92: 1 | G92: =-H92 -> -27.225 | H92: =0.33*gen!P92 -> 27.225 | I92: 1 | J92: FALSE | K92: TRUE | L92: 0 | M92: WP | N92: TRUE | O92: 0 | P92: 82.5
A93: 91 | B93: Windpark Delfzijl Noord | C93: 8 | D93: =0.35*gen!P93 -> 21.945 | E93: 1 | G93: =-H93 -> -20.691 | H93: =0.33*gen!P93 -> 20.691 | I93: 1 | J93: FALSE | K93: TRUE | L93: 0 | M93: WP | N93: TRUE | O93: 0 | P93: 62.7
A94: 92 | B94: Windpark Slufterdam | C94: 28 | D94: =0.35*gen!P94 -> 17.64 | E94: 1 | G94: =-H94 -> -16.632 | H94: =0.33*gen!P94 -> 16.632 | I94: 1 | J94: FALSE | K94: TRUE | L94: 0 | M94: WP | N94: TRUE | O94: 0 | P94: 50.4
...

Sheet ext_grid
B1: name | C1: bus | D1: vm_pu | E1: va_degree | F1: slack_weight | G1: in_service | H1: p_mw | I1: min_p_mw | J1: max_p_mw | K1: min_q_mvar | L1: max_q_mvar | M1: controllable
A2: 0 | B2: 380kV Germany (Wesel) - Doetichem | C2: 40 | D2: 1 | E2: 0 | F2: 1 | G2: TRUE | H2: 100 | I2: -1972 | J2: 1972 | K2: -5000 | L2: 5000 | M2: FALSE

Sheet line
B1: name | C1: std_type | D1: from_bus | E1: to_bus | F1: length_km | G1: r_ohm_per_km | H1: x_ohm_per_km | I1: c_nf_per_km | J1: g_us_per_km | K1: max_i_ka | L1: df | M1: parallel | N1: type | O1: in_service | P1: max_loading_percent
A2: 0 | B2: EEM220-RBB220-W | D2: 0 | E2: 6 | F2: 0.04 | G2: 0.05 | H2: 0.7 | I2: 10 | J2: 0 | K2: 4 | L2: 1 | M2: 1 | N2: 220kV | O2: TRUE | P2: 100
A3: 1 | B3: EEM220-RBB220-Z | D3: 0 | E3: 6 | F3: 0.04 | G3: 0.05 | H3: 0.7 | I3: 10 | J3: 0 | K3: 4 | L3: 1 | M3: 1 | N3: 220kV | O3: TRUE | P3: 100
A4: 2 | B4: HSW220-ENS220-W | D4: 2 | E4: 1 | F4: 31.4 | G4: 0.023853503 | H4: 0.26308917 | I4: 10 | J4: 0 | K4: 2.5 | L4: 1 | M4: 1 | N4: 220kV | O4: TRUE | P4: 100
A5: 3 | B5: HSW220-ENS220-Z | D5: 2 | E5: 1 | F5: 31.4 | G5: 0.023853503 | H5: 0.26308917 | I5: 10 | J5: 0 | K5: 2.5 | L5: 1 | M5: 1 | N5: 220kV | O5: TRUE | P5: 100
A6: 4 | B6: LSM220-VVL220-W | D6: 3 | E6: 7 | F6: 43.1 | G6: 0.023981481 | H6: 0.26407407 | I6: 10 | J6: 0 | K6: 2.5 | L6: 1 | M6: 1 | N6: 220kV | O6: TRUE | P6: 100
A7: 5 | B7: LSM220-VVL220-Z | D7: 3 | E7: 7 | F7: 43.1 | G7: 0.023981481 | H7: 0.26407407 | I7: 10 | J7: 0 | K7: 2.5 | L7: 1 | M7: 1 | N7: 220kV | O7: TRUE | P7: 100
A8: 6 | B8: LSM220-OHK220-W | D8: 3 | E8: 5 | F8: 28.5 | G8: 0.023894737 | H8: 0.26277193 | I8: 10 | J8: 0 | K8: 2.75 | L8: 1 | M8: 1 | N8: 220kV | O8: TRUE | P8: 100
A9: 7 | B9: LSM220-OHK220-Z | D9: 3 | E9: 5 | F9: 28.5 | G9: 0.023894737 | H9: 0.26277193 | I9: 10 | J9: 0 | K9: 2.75 | L9: 1 | M9: 1 | N9: 220kV | O9: TRUE | P9: 100
A10: 8 | B10: OHK220-ENS220-W | D10: 5 | E10: 1 | F10: 43.8 | G10: 0.02390411 | H10: 0.26289954 | I10: 10 | J10: 0 | K10: 2.5 | L10: 1 | M10: 1 | N10: 220kV | O10: TRUE | P10: 100
A11: 9 | B11: OHK220-ENS220-Z | D11: 5 | E11: 1 | F11: 43.8 | G11: 0.02390411 | H11: 0.26289954 | I11: 10 | J11: 0 | K11: 2.75 | L11: 1 | M11: 1 | N11: 220kV | O11: TRUE | P11: 100
A12: 10 | B12: RBB220-WEW220-G | D12: 6 | E12: 8 | F12: 25.6 | G12: 0.017070313 | H12: 0.24734375 | I12: 10 | J12: 0 | K12: 2.3 | L12: 1 | M12: 1 | N12: 220kV | O12: TRUE | P12: 100
A13: 11 | B13: RBB220-WEW220-P | D13: 6 | E13: 8 | F13: 25.6 | G13: 0.017070313 | H13: 0.24734375 | I13: 10 | J13: 0 | K13: 2.5 | L13: 1 | M13: 1 | N13: 220kV | O13: TRUE | P13: 100
... A34: 32 | B34: DTC380-HGL380-Z | D34: 17 | E34: 23 | F34: 58.7 | G34: 0.025400341 | H34: 0.27325383 | I34: 10 | J34: 0 | K34: 3.1 | L34: 1 | M34: 1 | N34: 380kV | O34: TRUE | P34: 100
A35: 33 | B35: DTC380-NDR380-W | D35: 17 | E35: 40 | F35: 10 | G35: =(0.0009*380*380)/(1000*10) -> 0.012996 | H35: =(0.03*380*380)/(1000*10) -> 0.4332 | I35: 0 | J35: 0 | K35: 4 | L35: 1 | M35: 1 | N35: 380kV | O35: TRUE | P35: 100
A36: 34 | B36: DTC380-NDR380-Z | D36: 17 | E36: 40 | F36: 10 | G36: =(0.0009*380*380)/(1000*10) -> 0.012996 | H36: =(0.03*380*380)/(1000*10) -> 0.4332 | I36: 0 | J36: 0 | K36: 4 | L36: 1 | M36: 1 | N36: 380kV | O36: TRUE | P36: 100
A37: 35 | B37: EEM380-MEE380-W | D37: 18 | E37: 27 | F37: 36.8 | G37: 0.013831522 | H37: 0.23828804 | I37: 10 | J37: 0 | K37: 4 | L37: 1 | M37: 1 | N37: 380kV | O37: TRUE | P37: 100
A38: 36 | B38: EEM380-MEE380-Z | D38: 18 | E38: 27 | F38: 36.8 | G38: 0.013831522 | H38: 0.23828804 | I38: 10 | J38: 0 | K38: 4 | L38: 1 | M38: 1 | N38: 380kV | O38: TRUE | P38: 100
A39: 37 | B39: ENS380-ZL380-W | D39: 20 | E39: 34 | F39: 32 | G39: 0.0253125 | H39: 0.27334375 | I39: 10 | J39: 0 | K39: 3.1 | L39: 1 | M39: 1 | N39: 380kV | O39: TRUE | P39: 100
A40: 38 | B40: ENS380-ZL380-Z | D40: 20 | E40: 34 | F40: 32 | G40: 0.0253125 | H40: 0.27334375 | I40: 10 | J40: 0 | K40: 3.1 | L40: 1 | M40: 1 | N40: 380kV | O40: TRUE | P40: 100
A41: 39 | B41: EOS380-EEM380-W | D41: 21 | E41: 18 | F41: 1.44 | G41: 0.013888889 | H41: 0.22916667 | I41: 10 | J41: 0 | K41: 4 | L41: 1 | M41: 1 | N41: 380kV | O41: TRUE | P41: 100
A42: 40 | B42: EOS380-EEM380-Z | D42: 21 | E42: 18 | F42: 1.44 | G42: 0.013888889 | H42: 0.22916667 | I42: 10 | J42: 0 | K42: 4 | L42: 1 | M42: 1 | N42: 380kV | O42: TRUE | P42: 100
A43: 41 | B43: GNA380-HGL380-W | D43: 39 | E43: 23 | F43: 10 | G43: =(0.0009*380*380)/(1000*10) -> 0.012996 | H43: =(0.03*380*380)/(1000*10) -> 0.4332 | I43: 0 | J43: 0 | K43: 2.5 | L43: 1 | M43: 1 | N43: 380kV | O43: TRUE | P43: 100
A44: 42 | B44: GNA380-HGL380-Z | D44: 39 | E44: 23 | F44: 10 | G44: =(0.0009*380*380)/(1000*10) -> 0.012996 | H44: =(0.03*380*380)/(1000*10) -> 0.4332 | I44: 0 | J44: 0 | K44: 2.5 | L44: 1 | M44: 1 | N44: 380kV | O44: TRUE | P44: 100
A45: 43 | B45: KIJ380-BKK380-W | D45: 24 | E45: 10 | F45: 20 | G45: 0.0235 | H45: 0.274 | I45: 10 | J45: 0 | K45: 2.5 | L45: 1 | M45: 1 | N45: 380kV | O45: TRUE | P45: 100
A46: 44 | B46: KIJ380-BWK380-W | D46: 24 | E46: 13 | F46: 18.5 | G46: 0.015297297 | H46: 0.24437838 | I46: 10 | J46: 0 | K46: 4 | L46: 1 | M46: 1 | N46: 380kV | O46: TRUE | P46: 100
A47: 45 | B47: KIJ380-BWK380-Z | D47: 24 | E47: 13 | F47: 18.5 | G47: 0.015297297 | H47: 0.24437838 | I47: 10 | J47: 0 | K47: 4 | L47: 1 | M47: 1 | N47: 380kV | O47: TRUE | P47: 100
A48: 46 | B48: KIJ380-GT380-W | D48: 24 | E48: 22 | F48: 34 | G48: 0.023382353 | H48: 0.27391176 | I48: 10 | J48: 0 | K48: 3.3 | L48: 1 | M48: 1 | N48: 380kV | O48: TRUE | P48: 100
A49: 47 | B49: KIJ380-GT380-Z | D49: 24 | E49: 22 | F49: 34 | G49: 0.023382353 | H49: 0.27391176 | I49: 10 | J49: 0 | K49: 3.3 | L49: 1 | M49: 1 | N49: 380kV | O49: TRUE | P49: 100
A50: 48 | B50: LLS380-ENS380-W | D50: 25 | E50: 20 | F50: 21 | G50: 0.023428571 | H50: 0.27252381 | I50: 10 | J50: 0 | K50: 4 | L50: 1 | M50: 1 | N50: 380kV | O50: TRUE | P50: 100
A51: 49 | B51: LLS380-ENS380-Z | D51: 25 | E51: 20 | F51: 21 | G51: 0.023428571 | H51: 0.27252381 | I51: 10 | J51: 0 | K51: 4 | L51: 1 | M51: 1 | N51: 380kV | O51: TRUE | P51: 100
A52: 50 | B52: MBT380-EHV380-W | D52: 26 | E52: 19 | F52: 48.7 | G52: 0.023264887 | H52: 0.27414784 | I52: 10 | J52: 0 | K52: 3.3 | L52: 1 | M52: 1 | N52: 380kV | O52: TRUE | P52: 100
A53: 51 | B53: MBT380-EHV380-Z | D53: 26 | E53: 19 | F53: 48.7 | G53: 0.023264887 | H53: 0.27414784 | I53: 10 | J53: 0 | K53: 3.3 | L53: 1 | M53: 1 | N53: 380kV | O53: TRUE | P53: 100
A54: 52 | B54: MBT380-RMK380-W | D54: 26 | E54: 41 | F54: 10 | G54: =(0.0009*380*380)/(1000*10) -> 0.012996 | H54: =(0.03*380*380)/(1000*10) -> 0.4332 | I54: 0 | J54: 0 | K54: 2.6 | L54: 1 | M54: 1 | N54: 380kV | O54: TRUE | P54: 100
A55: 53 | B55: MBT380-SDF380-Z | D55: 26 | E55: 42 | F55: 10 | G55: =(0.0009*380*380)/(1000*10) -> 0.012996 | H55: =(0.03*380*380)/(1000*10) -> 0.4332 | I55: 0 | J55: 0 | K55: 2.6 | L55: 1 | M55: 1 | N55: 380kV | O55: TRUE | P55: 100
A56: 54 | B56: MEE380-DIL380-W | D56: 27 | E56: 38 | F56: 10 | G56: =(0.0009*380*380)/(1000*10) -> 0.012996 | H56: =(0.03*380*380)/(1000*10) -> 0.4332 | I56: 0 | J56: 0 | K56: 1.52 | L56: 1 | M56: 1 | N56: 380kV | O56: TRUE | P56: 100
A57: 55 | B57: MEE380-DIL380-Z | D57: 27 | E57: 38 | F57: 10 | G57: =(0.0009*380*380)/(1000*10) -> 0.012996 | H57: =(0.03*380*380)/(1000*10) -> 0.4332 | I57: 0 | J57: 0 | K57: 1.52 | L57: 1 | M57: 1 | N57: 380kV | O57: TRUE | P57: 100
A58: 56 | B58: MVL380-CST380-W | D58: 28 | E58: 14 | F58: 66 | G58: 0.015384615 | H58: 0.24230769 | I58: 10 | J58: 0 | K58: 4 | L58: 1 | M58: 1 | N58: 380kV | O58: TRUE | P58: 100
A59: 57 | B59: MVL380-CST380-Z | D59: 28 | E59: 14 | F59: 66 | G59: 0.015384615 | H59: 0.24230769 | I59: 10 | J59: 0 | K59: 4 | L59: 1 | M59: 1 | N59: 380kV | O59: TRUE | P59: 100
A60: 58 | B60: OZN380-DIM380-G | D60: 29 | E60: 15 | F60: 15.2 | G60: 0.023355263 | H60: 0.27375 | I60: 10 | J60: 0 | K60: 3 | L60: 1 | M60: 1 | N60: 380kV | O60: TRUE | P60: 100
...

Sheet trafo
B1: name | C1: std_type | D1: hv_bus | E1: lv_bus | F1: sn_mva | G1: vn_hv_kv | H1: vn_lv_kv | I1: vk_percent | J1: vkr_percent | K1: pfe_kw | L1: i0_percent | M1: shift_degree | N1: tap_side | O1: tap_neutral | P1: tap_min | Q1: tap_max | R1: tap_step_percent | S1: tap_step_degree | T1: tap_pos | U1: tap_phase_shifter | V1: parallel | W1: df | X1: in_service | Y1: tp_pos | Z1: max_loading_percent
A2: 0 | B2: Transformer EEM380 - EEM220 | D2: 18 | E2: 0 | F2: 2250 | G2: 380 | H2: 220 | I2: 8 | J2: 0.06 | K2: 0 | L2: 0 | M2: 0 | U2: FALSE | V2: 1 | W2: 1 | X2: TRUE | Y2: 0 | Z2: 100
A3: 1 | B3: Transformer ENS380 - ENS220 | D3: 20 | E3: 1 | F3: 1000 | G3: 380 | H3: 220 | I3: 8 | J3: 0.06 | K3: 0 | L3: 0 | M3: 0 | U3: FALSE | V3: 1 | W3: 1 | X3: TRUE | Y3: 0 | Z3: 100
A4: 2 | B4: Transformer MEE380 - MEE220 | D4: 27 | E4: 4 | F4: 750 | G4: 380 | H4: 220 | I4: 8 | J4: 0.06 | K4: 0 | L4: 0 | M4: 0 | U4: FALSE | V4: 1 | W4: 1 | X4: TRUE | Y4: 0 | Z4: 100
A5: 3 | B5: Transformer VLL380 - VLL220 | D5: 45 | E5: 7 | F5: 5400 | G5: 380 | H5: 220 | I5: 8 | J5: 0.06 | K5: 0 | L5: 0 | M5: 0 | U5: FALSE | V5: 1 | W5: 1 | X5: TRUE | Y5: 0 | Z5: 100

Sheet bus_geodata
B1: x | C1: y | D1: coords
A2: 0 | B2: 6.8741753 | C2: 53.42445
A3: 1 | B3: 5.811136 | C3: 52.618528
A4: 2 | B4: 6.1883994 | C4: 52.532048
A5: 3 | B5: 5.8772615 | C5: 53.189973
A6: 4 | B6: 6.9463037 | C6: 53.123551
A7: 5 | B7: 5.873315 | C7: 52.9739
A8: 6 | B8: 6.8738795 | C8: 53.424161
A9: 7 | B9: 6.4748641 | C9: 53.210517
A10: 8 | B10: 6.9576607 | C10: 53.302216
A11: 9 | B11: 6.5227311 | C11: 53.009138
A12: 10 | B12: 4.9863952 | C12: 52.160142
A13: 11 | B13: 3.7309743 | C13: 51.433105
... A54: 52 | B54: 6.8348262 | C54: 52.728921

Sheet dtypes
B1: element | C1: column | D1: dtype
A2: 0 | B2: bus | C2: name | D2: object
A3: 1 | B3: bus | C3: vn_kv | D3: float64
A4: 2 | B4: bus | C4: type | D4: object
A5: 3 | B5: bus | C5: zone | D5: object
A6: 4 | B6: bus | C6: in_service | D6: bool
A7: 5 | B7: bus | C7: min_vm_pu | D7: float64
A8: 6 | B8: bus | C8: max_vm_pu | D8: float64
A9: 7 | B9: gen | C9: name | D9: object
A10: 8 | B10: gen | C10: bus | D10: uint32
A11: 9 | B11: gen | C11: p_mw | D11: float64
A12: 10 | B12: gen | C12: vm_pu | D12: float64
A13: 11 | B13: gen | C13: sn_mva | D13: float64
... A78: 76 | B78: bus_geodata | C78: coords | D78: object

Sheet parameters
B1: version | C1: format_version | D1: converged | E1: OPF_converged | F1: name | G1: f_hz | H1: sn_mva
A2: 0 | B2: 2.13.1 | C2: 2.12.0 | D2: FALSE | E2: FALSE | G2: 50 | H2: 1
